[2025-09-02T23:14:02.358+0000] {local_task_job_runner.py:120} INFO - ::group::Pre task execution logs
[2025-09-02T23:14:02.387+0000] {taskinstance.py:2076} INFO - Dependencies all met for dep_context=non-requeueable deps ti=<TaskInstance: market_table_foreign.activity_HNX scheduled__2025-09-02T23:13:00+00:00 [queued]>
[2025-09-02T23:14:02.397+0000] {taskinstance.py:2076} INFO - Dependencies all met for dep_context=requeueable deps ti=<TaskInstance: market_table_foreign.activity_HNX scheduled__2025-09-02T23:13:00+00:00 [queued]>
[2025-09-02T23:14:02.398+0000] {taskinstance.py:2306} INFO - Starting attempt 1 of 11
[2025-09-02T23:14:02.429+0000] {taskinstance.py:2330} INFO - Executing <Task(PythonOperator): activity_HNX> on 2025-09-02 23:13:00+00:00
[2025-09-02T23:14:02.445+0000] {standard_task_runner.py:63} INFO - Started process 2615998 to run task
[2025-09-02T23:14:02.464+0000] {standard_task_runner.py:90} INFO - Running: ['***', 'tasks', 'run', 'market_table_foreign', 'activity_HNX', 'scheduled__2025-09-02T23:13:00+00:00', '--job-id', '63747', '--raw', '--subdir', 'DAGS_FOLDER/dag_market_live.py', '--cfg-path', '/tmp/tmpsijypitt']
[2025-09-02T23:14:02.468+0000] {standard_task_runner.py:91} INFO - Job 63747: Subtask activity_HNX
[2025-09-02T23:14:02.539+0000] {task_command.py:426} INFO - Running <TaskInstance: market_table_foreign.activity_HNX scheduled__2025-09-02T23:13:00+00:00 [running]> on host 1877907bc043
[2025-09-02T23:14:02.641+0000] {taskinstance.py:2648} INFO - Exporting env vars: AIRFLOW_CTX_DAG_OWNER='***' AIRFLOW_CTX_DAG_ID='market_table_foreign' AIRFLOW_CTX_TASK_ID='activity_HNX' AIRFLOW_CTX_EXECUTION_DATE='2025-09-02T23:13:00+00:00' AIRFLOW_CTX_TRY_NUMBER='1' AIRFLOW_CTX_DAG_RUN_ID='scheduled__2025-09-02T23:13:00+00:00'
[2025-09-02T23:14:02.643+0000] {taskinstance.py:430} INFO - ::endgroup::
[2025-09-02T23:14:02.656+0000] {activity_HNX.py:17} INFO - Kết nối DB
[2025-09-02T23:14:02.908+0000] {activity_HNX.py:55} ERROR - Lỗi lưu activity_HNX
Traceback (most recent call last):
  File "/opt/airflow/dags/utils/market_data/activity_HNX.py", line 35, in activity_HNX
    point=float(dfindex.loc[dfindex['symbol']=='HNXIndex','point'].values[0])
IndexError: index 0 is out of bounds for axis 0 with size 0
[2025-09-02T23:14:02.909+0000] {python.py:237} INFO - Done. Returned value was: None
[2025-09-02T23:14:02.910+0000] {taskinstance.py:441} INFO - ::group::Post task execution logs
[2025-09-02T23:14:02.925+0000] {taskinstance.py:1206} INFO - Marking task as SUCCESS. dag_id=market_table_foreign, task_id=activity_HNX, run_id=scheduled__2025-09-02T23:13:00+00:00, execution_date=20250902T231300, start_date=20250902T231402, end_date=20250902T231402
[2025-09-02T23:14:02.994+0000] {local_task_job_runner.py:240} INFO - Task exited with return code 0
[2025-09-02T23:14:03.015+0000] {taskinstance.py:3498} INFO - 0 downstream tasks scheduled from follow-on schedule check
[2025-09-02T23:14:03.016+0000] {local_task_job_runner.py:222} INFO - ::endgroup::
