[2025-09-08T00:40:01.913+0000] {local_task_job_runner.py:120} INFO - ::group::Pre task execution logs
[2025-09-08T00:40:01.940+0000] {taskinstance.py:2076} INFO - Dependencies all met for dep_context=non-requeueable deps ti=<TaskInstance: foreign_1_live.save_foreign_1 scheduled__2025-09-08T00:39:00+00:00 [queued]>
[2025-09-08T00:40:01.948+0000] {taskinstance.py:2076} INFO - Dependencies all met for dep_context=requeueable deps ti=<TaskInstance: foreign_1_live.save_foreign_1 scheduled__2025-09-08T00:39:00+00:00 [queued]>
[2025-09-08T00:40:01.949+0000] {taskinstance.py:2306} INFO - Starting attempt 1 of 11
[2025-09-08T00:40:01.963+0000] {taskinstance.py:2330} INFO - Executing <Task(PythonOperator): save_foreign_1> on 2025-09-08 00:39:00+00:00
[2025-09-08T00:40:01.970+0000] {standard_task_runner.py:63} INFO - Started process 285980 to run task
[2025-09-08T00:40:01.974+0000] {standard_task_runner.py:90} INFO - Running: ['***', 'tasks', 'run', 'foreign_1_live', 'save_foreign_1', 'scheduled__2025-09-08T00:39:00+00:00', '--job-id', '155007', '--raw', '--subdir', 'DAGS_FOLDER/dag_foreign_1_live.py', '--cfg-path', '/tmp/tmpeyy7shl5']
[2025-09-08T00:40:01.978+0000] {standard_task_runner.py:91} INFO - Job 155007: Subtask save_foreign_1
[2025-09-08T00:40:02.033+0000] {task_command.py:426} INFO - Running <TaskInstance: foreign_1_live.save_foreign_1 scheduled__2025-09-08T00:39:00+00:00 [running]> on host 8d9cea3aac78
[2025-09-08T00:40:02.199+0000] {taskinstance.py:2648} INFO - Exporting env vars: AIRFLOW_CTX_DAG_OWNER='***' AIRFLOW_CTX_DAG_ID='foreign_1_live' AIRFLOW_CTX_TASK_ID='save_foreign_1' AIRFLOW_CTX_EXECUTION_DATE='2025-09-08T00:39:00+00:00' AIRFLOW_CTX_TRY_NUMBER='1' AIRFLOW_CTX_DAG_RUN_ID='scheduled__2025-09-08T00:39:00+00:00'
[2025-09-08T00:40:02.201+0000] {taskinstance.py:430} INFO - ::endgroup::
[2025-09-08T00:40:02.220+0000] {foreign_1.py:18} INFO - Kết nối DB
[2025-09-08T00:40:02.457+0000] {foreign_1.py:30} ERROR - Lỗi lưu foreign_ALL
Traceback (most recent call last):
  File "/opt/airflow/dags/utils/market_history/foreign/foreign_1.py", line 20, in foreign
    foreign=foreign_history(f"{symbol}")
  File "/opt/airflow/dags/utils/market_history/foreign/foreign_history_1.py", line 49, in foreign_history
    data=data.drop(columns=['group','dataType','timeFrame'])
  File "/home/airflow/.local/lib/python3.10/site-packages/pandas/core/frame.py", line 5344, in drop
    return super().drop(
  File "/home/airflow/.local/lib/python3.10/site-packages/pandas/core/generic.py", line 4711, in drop
    obj = obj._drop_axis(labels, axis, level=level, errors=errors)
  File "/home/airflow/.local/lib/python3.10/site-packages/pandas/core/generic.py", line 4753, in _drop_axis
    new_axis = axis.drop(labels, errors=errors)
  File "/home/airflow/.local/lib/python3.10/site-packages/pandas/core/indexes/base.py", line 7000, in drop
    raise KeyError(f"{labels[mask].tolist()} not found in axis")
KeyError: "['group', 'dataType', 'timeFrame'] not found in axis"
[2025-09-08T00:40:02.467+0000] {foreign_1.py:18} INFO - Kết nối DB
[2025-09-08T00:40:02.637+0000] {foreign_1.py:30} ERROR - Lỗi lưu foreign_HOSE
Traceback (most recent call last):
  File "/opt/airflow/dags/utils/market_history/foreign/foreign_1.py", line 20, in foreign
    foreign=foreign_history(f"{symbol}")
  File "/opt/airflow/dags/utils/market_history/foreign/foreign_history_1.py", line 49, in foreign_history
    data=data.drop(columns=['group','dataType','timeFrame'])
  File "/home/airflow/.local/lib/python3.10/site-packages/pandas/core/frame.py", line 5344, in drop
    return super().drop(
  File "/home/airflow/.local/lib/python3.10/site-packages/pandas/core/generic.py", line 4711, in drop
    obj = obj._drop_axis(labels, axis, level=level, errors=errors)
  File "/home/airflow/.local/lib/python3.10/site-packages/pandas/core/generic.py", line 4753, in _drop_axis
    new_axis = axis.drop(labels, errors=errors)
  File "/home/airflow/.local/lib/python3.10/site-packages/pandas/core/indexes/base.py", line 7000, in drop
    raise KeyError(f"{labels[mask].tolist()} not found in axis")
KeyError: "['group', 'dataType', 'timeFrame'] not found in axis"
[2025-09-08T00:40:02.640+0000] {foreign_1.py:18} INFO - Kết nối DB
[2025-09-08T00:40:02.761+0000] {foreign_1.py:30} ERROR - Lỗi lưu foreign_HNX
Traceback (most recent call last):
  File "/opt/airflow/dags/utils/market_history/foreign/foreign_1.py", line 20, in foreign
    foreign=foreign_history(f"{symbol}")
  File "/opt/airflow/dags/utils/market_history/foreign/foreign_history_1.py", line 49, in foreign_history
    data=data.drop(columns=['group','dataType','timeFrame'])
  File "/home/airflow/.local/lib/python3.10/site-packages/pandas/core/frame.py", line 5344, in drop
    return super().drop(
  File "/home/airflow/.local/lib/python3.10/site-packages/pandas/core/generic.py", line 4711, in drop
    obj = obj._drop_axis(labels, axis, level=level, errors=errors)
  File "/home/airflow/.local/lib/python3.10/site-packages/pandas/core/generic.py", line 4753, in _drop_axis
    new_axis = axis.drop(labels, errors=errors)
  File "/home/airflow/.local/lib/python3.10/site-packages/pandas/core/indexes/base.py", line 7000, in drop
    raise KeyError(f"{labels[mask].tolist()} not found in axis")
KeyError: "['group', 'dataType', 'timeFrame'] not found in axis"
[2025-09-08T00:40:02.764+0000] {foreign_1.py:18} INFO - Kết nối DB
[2025-09-08T00:40:02.872+0000] {foreign_1.py:30} ERROR - Lỗi lưu foreign_UPCOM
Traceback (most recent call last):
  File "/opt/airflow/dags/utils/market_history/foreign/foreign_1.py", line 20, in foreign
    foreign=foreign_history(f"{symbol}")
  File "/opt/airflow/dags/utils/market_history/foreign/foreign_history_1.py", line 49, in foreign_history
    data=data.drop(columns=['group','dataType','timeFrame'])
  File "/home/airflow/.local/lib/python3.10/site-packages/pandas/core/frame.py", line 5344, in drop
    return super().drop(
  File "/home/airflow/.local/lib/python3.10/site-packages/pandas/core/generic.py", line 4711, in drop
    obj = obj._drop_axis(labels, axis, level=level, errors=errors)
  File "/home/airflow/.local/lib/python3.10/site-packages/pandas/core/generic.py", line 4753, in _drop_axis
    new_axis = axis.drop(labels, errors=errors)
  File "/home/airflow/.local/lib/python3.10/site-packages/pandas/core/indexes/base.py", line 7000, in drop
    raise KeyError(f"{labels[mask].tolist()} not found in axis")
KeyError: "['group', 'dataType', 'timeFrame'] not found in axis"
[2025-09-08T00:40:02.874+0000] {python.py:237} INFO - Done. Returned value was: None
[2025-09-08T00:40:02.875+0000] {taskinstance.py:441} INFO - ::group::Post task execution logs
[2025-09-08T00:40:02.888+0000] {taskinstance.py:1206} INFO - Marking task as SUCCESS. dag_id=foreign_1_live, task_id=save_foreign_1, run_id=scheduled__2025-09-08T00:39:00+00:00, execution_date=20250908T003900, start_date=20250908T004001, end_date=20250908T004002
[2025-09-08T00:40:02.949+0000] {local_task_job_runner.py:240} INFO - Task exited with return code 0
[2025-09-08T00:40:02.971+0000] {local_task_job_runner.py:222} INFO - ::endgroup::
