[2025-09-05T08:00:02.055+0000] {local_task_job_runner.py:120} INFO - ::group::Pre task execution logs
[2025-09-05T08:00:02.080+0000] {taskinstance.py:2076} INFO - Dependencies all met for dep_context=non-requeueable deps ti=<TaskInstance: activity.activity_HNX scheduled__2025-09-05T07:59:00+00:00 [queued]>
[2025-09-05T08:00:02.089+0000] {taskinstance.py:2076} INFO - Dependencies all met for dep_context=requeueable deps ti=<TaskInstance: activity.activity_HNX scheduled__2025-09-05T07:59:00+00:00 [queued]>
[2025-09-05T08:00:02.089+0000] {taskinstance.py:2306} INFO - Starting attempt 1 of 11
[2025-09-05T08:00:02.102+0000] {taskinstance.py:2330} INFO - Executing <Task(PythonOperator): activity_HNX> on 2025-09-05 07:59:00+00:00
[2025-09-05T08:00:02.111+0000] {standard_task_runner.py:63} INFO - Started process 3155894 to run task
[2025-09-05T08:00:02.115+0000] {standard_task_runner.py:90} INFO - Running: ['***', 'tasks', 'run', 'activity', 'activity_HNX', 'scheduled__2025-09-05T07:59:00+00:00', '--job-id', '112028', '--raw', '--subdir', 'DAGS_FOLDER/dag_activity.py', '--cfg-path', '/tmp/tmphxq78pa4']
[2025-09-05T08:00:02.118+0000] {standard_task_runner.py:91} INFO - Job 112028: Subtask activity_HNX
[2025-09-05T08:00:02.179+0000] {task_command.py:426} INFO - Running <TaskInstance: activity.activity_HNX scheduled__2025-09-05T07:59:00+00:00 [running]> on host 1877907bc043
[2025-09-05T08:00:02.314+0000] {taskinstance.py:2648} INFO - Exporting env vars: AIRFLOW_CTX_DAG_OWNER='***' AIRFLOW_CTX_DAG_ID='activity' AIRFLOW_CTX_TASK_ID='activity_HNX' AIRFLOW_CTX_EXECUTION_DATE='2025-09-05T07:59:00+00:00' AIRFLOW_CTX_TRY_NUMBER='1' AIRFLOW_CTX_DAG_RUN_ID='scheduled__2025-09-05T07:59:00+00:00'
[2025-09-05T08:00:02.316+0000] {taskinstance.py:430} INFO - ::endgroup::
[2025-09-05T08:00:02.340+0000] {activity_HNX.py:17} INFO - Kết nối DB
[2025-09-05T08:00:02.393+0000] {activity_HNX.py:55} ERROR - Lỗi lưu activity_HNX
Traceback (most recent call last):
  File "/home/airflow/.local/lib/python3.10/site-packages/sqlalchemy/engine/base.py", line 1910, in _execute_context
    self.dialect.do_execute(
  File "/home/airflow/.local/lib/python3.10/site-packages/sqlalchemy/engine/default.py", line 736, in do_execute
    cursor.execute(statement, parameters)
psycopg2.errors.UndefinedTable: relation "history_data.eboard_table" does not exist
LINE 1: SELECT * FROM "history_data"."eboard_table"
                      ^


The above exception was the direct cause of the following exception:

Traceback (most recent call last):
  File "/opt/airflow/dags/utils/market_data/activity/activity_HNX.py", line 18, in activity_HNX
    df = pd.read_sql('SELECT * FROM "history_data"."eboard_table"', con=enginedb).sort_values(by='symbol',ascending=True)
  File "/home/airflow/.local/lib/python3.10/site-packages/pandas/io/sql.py", line 682, in read_sql
    return pandas_sql.read_query(
  File "/home/airflow/.local/lib/python3.10/site-packages/pandas/io/sql.py", line 1776, in read_query
    result = self.execute(sql, params)
  File "/home/airflow/.local/lib/python3.10/site-packages/pandas/io/sql.py", line 1599, in execute
    return self.con.exec_driver_sql(sql, *args)
  File "/home/airflow/.local/lib/python3.10/site-packages/sqlalchemy/engine/base.py", line 1770, in exec_driver_sql
    return self._exec_driver_sql(
  File "/home/airflow/.local/lib/python3.10/site-packages/sqlalchemy/engine/base.py", line 1674, in _exec_driver_sql
    ret = self._execute_context(
  File "/home/airflow/.local/lib/python3.10/site-packages/sqlalchemy/engine/base.py", line 1953, in _execute_context
    self._handle_dbapi_exception(
  File "/home/airflow/.local/lib/python3.10/site-packages/sqlalchemy/engine/base.py", line 2134, in _handle_dbapi_exception
    util.raise_(
  File "/home/airflow/.local/lib/python3.10/site-packages/sqlalchemy/util/compat.py", line 211, in raise_
    raise exception
  File "/home/airflow/.local/lib/python3.10/site-packages/sqlalchemy/engine/base.py", line 1910, in _execute_context
    self.dialect.do_execute(
  File "/home/airflow/.local/lib/python3.10/site-packages/sqlalchemy/engine/default.py", line 736, in do_execute
    cursor.execute(statement, parameters)
sqlalchemy.exc.ProgrammingError: (psycopg2.errors.UndefinedTable) relation "history_data.eboard_table" does not exist
LINE 1: SELECT * FROM "history_data"."eboard_table"
                      ^

[SQL: SELECT * FROM "history_data"."eboard_table"]
(Background on this error at: https://sqlalche.me/e/14/f405)
[2025-09-05T08:00:02.398+0000] {python.py:237} INFO - Done. Returned value was: None
[2025-09-05T08:00:02.399+0000] {taskinstance.py:441} INFO - ::group::Post task execution logs
[2025-09-05T08:00:02.417+0000] {taskinstance.py:1206} INFO - Marking task as SUCCESS. dag_id=activity, task_id=activity_HNX, run_id=scheduled__2025-09-05T07:59:00+00:00, execution_date=20250905T075900, start_date=20250905T080002, end_date=20250905T080002
[2025-09-05T08:00:02.487+0000] {local_task_job_runner.py:240} INFO - Task exited with return code 0
[2025-09-05T08:00:02.516+0000] {local_task_job_runner.py:222} INFO - ::endgroup::
