[2025-09-05T12:07:38.174+0000] {local_task_job_runner.py:120} INFO - ::group::Pre task execution logs
[2025-09-05T12:07:38.212+0000] {taskinstance.py:2076} INFO - Dependencies all met for dep_context=non-requeueable deps ti=<TaskInstance: news_pipeline.add_postgre manual__2025-09-05T11:09:55.305363+00:00 [queued]>
[2025-09-05T12:07:38.224+0000] {taskinstance.py:2076} INFO - Dependencies all met for dep_context=requeueable deps ti=<TaskInstance: news_pipeline.add_postgre manual__2025-09-05T11:09:55.305363+00:00 [queued]>
[2025-09-05T12:07:38.224+0000] {taskinstance.py:2306} INFO - Starting attempt 15 of 25
[2025-09-05T12:07:38.244+0000] {taskinstance.py:2330} INFO - Executing <Task(PythonOperator): add_postgre> on 2025-09-05 11:09:55.305363+00:00
[2025-09-05T12:07:38.256+0000] {standard_task_runner.py:63} INFO - Started process 3205732 to run task
[2025-09-05T12:07:38.261+0000] {standard_task_runner.py:90} INFO - Running: ['***', 'tasks', 'run', 'news_pipeline', 'add_postgre', 'manual__2025-09-05T11:09:55.305363+00:00', '--job-id', '114927', '--raw', '--subdir', 'DAGS_FOLDER/dag_news.py', '--cfg-path', '/tmp/tmp9ejeczin']
[2025-09-05T12:07:38.264+0000] {standard_task_runner.py:91} INFO - Job 114927: Subtask add_postgre
[2025-09-05T12:07:38.320+0000] {task_command.py:426} INFO - Running <TaskInstance: news_pipeline.add_postgre manual__2025-09-05T11:09:55.305363+00:00 [running]> on host 1877907bc043
[2025-09-05T12:07:38.408+0000] {taskinstance.py:2648} INFO - Exporting env vars: AIRFLOW_CTX_DAG_OWNER='***' AIRFLOW_CTX_DAG_ID='news_pipeline' AIRFLOW_CTX_TASK_ID='add_postgre' AIRFLOW_CTX_EXECUTION_DATE='2025-09-05T11:09:55.305363+00:00' AIRFLOW_CTX_TRY_NUMBER='15' AIRFLOW_CTX_DAG_RUN_ID='manual__2025-09-05T11:09:55.305363+00:00'
[2025-09-05T12:07:38.409+0000] {taskinstance.py:430} INFO - ::endgroup::
[2025-09-05T12:07:38.456+0000] {add_postgre.py:46} ERROR - ❌ Lỗi trong add_postgres: Message: session not created
from unknown error: no chrome binary at /snap/bin/chromium; For documentation on this error, please visit: https://www.selenium.dev/documentation/webdriver/troubleshooting/errors#sessionnotcreatedexception
Stacktrace:
#0 0x556a66a137da <unknown>
#1 0x556a664b82e0 <unknown>
#2 0x556a664f0008 <unknown>
#3 0x556a664edad7 <unknown>
#4 0x556a6653de9e <unknown>
#5 0x556a6653d466 <unknown>
#6 0x556a6652f683 <unknown>
#7 0x556a664fbb5b <unknown>
#8 0x556a664fcf31 <unknown>
#9 0x556a669d872b <unknown>
#10 0x556a669dc534 <unknown>
#11 0x556a669bf229 <unknown>
#12 0x556a669dd0d8 <unknown>
#13 0x556a669a361f <unknown>
#14 0x556a66a00dd8 <unknown>
#15 0x556a66a00fb6 <unknown>
#16 0x556a66a12af6 <unknown>
#17 0x7f581d052134 <unknown>

[2025-09-05T12:07:38.456+0000] {taskinstance.py:441} INFO - ::group::Post task execution logs
[2025-09-05T12:07:38.457+0000] {taskinstance.py:2905} ERROR - Task failed with exception
Traceback (most recent call last):
  File "/home/airflow/.local/lib/python3.10/site-packages/airflow/models/taskinstance.py", line 465, in _execute_task
    result = _execute_callable(context=context, **execute_callable_kwargs)
  File "/home/airflow/.local/lib/python3.10/site-packages/airflow/models/taskinstance.py", line 432, in _execute_callable
    return execute_callable(context=context, **execute_callable_kwargs)
  File "/home/airflow/.local/lib/python3.10/site-packages/airflow/models/baseoperator.py", line 400, in wrapper
    return func(self, *args, **kwargs)
  File "/home/airflow/.local/lib/python3.10/site-packages/airflow/operators/python.py", line 235, in execute
    return_value = self.execute_callable()
  File "/home/airflow/.local/lib/python3.10/site-packages/airflow/operators/python.py", line 252, in execute_callable
    return self.python_callable(*self.op_args, **self.op_kwargs)
  File "/opt/airflow/dags/utils/new_pipeline/add_postgre.py", line 11, in add_postgres
    df=tintuc()
  File "/opt/airflow/dags/utils/new_pipeline/merge.py", line 7, in tintuc
    df1=vietstock()
  File "/opt/airflow/dags/utils/new_pipeline/vietstock_ngay.py", line 28, in vietstock
    driver=webdriver.Chrome(service=Service('/usr/bin/chromedriver'),options=Chrome_option)
  File "/home/airflow/.local/lib/python3.10/site-packages/selenium/webdriver/chrome/webdriver.py", line 47, in __init__
    super().__init__(
  File "/home/airflow/.local/lib/python3.10/site-packages/selenium/webdriver/chromium/webdriver.py", line 69, in __init__
    super().__init__(command_executor=executor, options=options)
  File "/home/airflow/.local/lib/python3.10/site-packages/selenium/webdriver/remote/webdriver.py", line 261, in __init__
    self.start_session(capabilities)
  File "/home/airflow/.local/lib/python3.10/site-packages/selenium/webdriver/remote/webdriver.py", line 362, in start_session
    response = self.execute(Command.NEW_SESSION, caps)["value"]
  File "/home/airflow/.local/lib/python3.10/site-packages/selenium/webdriver/remote/webdriver.py", line 454, in execute
    self.error_handler.check_response(response)
  File "/home/airflow/.local/lib/python3.10/site-packages/selenium/webdriver/remote/errorhandler.py", line 232, in check_response
    raise exception_class(message, screen, stacktrace)
selenium.common.exceptions.SessionNotCreatedException: Message: session not created
from unknown error: no chrome binary at /snap/bin/chromium; For documentation on this error, please visit: https://www.selenium.dev/documentation/webdriver/troubleshooting/errors#sessionnotcreatedexception
Stacktrace:
#0 0x556a66a137da <unknown>
#1 0x556a664b82e0 <unknown>
#2 0x556a664f0008 <unknown>
#3 0x556a664edad7 <unknown>
#4 0x556a6653de9e <unknown>
#5 0x556a6653d466 <unknown>
#6 0x556a6652f683 <unknown>
#7 0x556a664fbb5b <unknown>
#8 0x556a664fcf31 <unknown>
#9 0x556a669d872b <unknown>
#10 0x556a669dc534 <unknown>
#11 0x556a669bf229 <unknown>
#12 0x556a669dd0d8 <unknown>
#13 0x556a669a361f <unknown>
#14 0x556a66a00dd8 <unknown>
#15 0x556a66a00fb6 <unknown>
#16 0x556a66a12af6 <unknown>
#17 0x7f581d052134 <unknown>

[2025-09-05T12:07:38.469+0000] {taskinstance.py:1206} INFO - Marking task as UP_FOR_RETRY. dag_id=news_pipeline, task_id=add_postgre, run_id=manual__2025-09-05T11:09:55.305363+00:00, execution_date=20250905T110955, start_date=20250905T120738, end_date=20250905T120738
[2025-09-05T12:07:38.481+0000] {standard_task_runner.py:110} ERROR - Failed to execute job 114927 for task add_postgre (Message: session not created
from unknown error: no chrome binary at /snap/bin/chromium; For documentation on this error, please visit: https://www.selenium.dev/documentation/webdriver/troubleshooting/errors#sessionnotcreatedexception
Stacktrace:
#0 0x556a66a137da <unknown>
#1 0x556a664b82e0 <unknown>
#2 0x556a664f0008 <unknown>
#3 0x556a664edad7 <unknown>
#4 0x556a6653de9e <unknown>
#5 0x556a6653d466 <unknown>
#6 0x556a6652f683 <unknown>
#7 0x556a664fbb5b <unknown>
#8 0x556a664fcf31 <unknown>
#9 0x556a669d872b <unknown>
#10 0x556a669dc534 <unknown>
#11 0x556a669bf229 <unknown>
#12 0x556a669dd0d8 <unknown>
#13 0x556a669a361f <unknown>
#14 0x556a66a00dd8 <unknown>
#15 0x556a66a00fb6 <unknown>
#16 0x556a66a12af6 <unknown>
#17 0x7f581d052134 <unknown>
; 3205732)
[2025-09-05T12:07:38.513+0000] {local_task_job_runner.py:240} INFO - Task exited with return code 1
[2025-09-05T12:07:38.551+0000] {taskinstance.py:3498} INFO - 0 downstream tasks scheduled from follow-on schedule check
[2025-09-05T12:07:38.552+0000] {local_task_job_runner.py:222} INFO - ::endgroup::
