[2025-09-05T11:19:29.882+0000] {local_task_job_runner.py:120} INFO - ::group::Pre task execution logs
[2025-09-05T11:19:29.904+0000] {taskinstance.py:2076} INFO - Dependencies all met for dep_context=non-requeueable deps ti=<TaskInstance: news_pipeline.add_postgre manual__2025-09-05T11:09:55.305363+00:00 [queued]>
[2025-09-05T11:19:29.911+0000] {taskinstance.py:2076} INFO - Dependencies all met for dep_context=requeueable deps ti=<TaskInstance: news_pipeline.add_postgre manual__2025-09-05T11:09:55.305363+00:00 [queued]>
[2025-09-05T11:19:29.912+0000] {taskinstance.py:2306} INFO - Starting attempt 3 of 13
[2025-09-05T11:19:29.923+0000] {taskinstance.py:2330} INFO - Executing <Task(PythonOperator): add_postgre> on 2025-09-05 11:09:55.305363+00:00
[2025-09-05T11:19:29.930+0000] {standard_task_runner.py:63} INFO - Started process 3196853 to run task
[2025-09-05T11:19:29.934+0000] {standard_task_runner.py:90} INFO - Running: ['***', 'tasks', 'run', 'news_pipeline', 'add_postgre', 'manual__2025-09-05T11:09:55.305363+00:00', '--job-id', '114380', '--raw', '--subdir', 'DAGS_FOLDER/dag_news.py', '--cfg-path', '/tmp/tmppg_0_5k9']
[2025-09-05T11:19:29.937+0000] {standard_task_runner.py:91} INFO - Job 114380: Subtask add_postgre
[2025-09-05T11:19:29.985+0000] {task_command.py:426} INFO - Running <TaskInstance: news_pipeline.add_postgre manual__2025-09-05T11:09:55.305363+00:00 [running]> on host 1877907bc043
[2025-09-05T11:19:30.058+0000] {taskinstance.py:2648} INFO - Exporting env vars: AIRFLOW_CTX_DAG_OWNER='***' AIRFLOW_CTX_DAG_ID='news_pipeline' AIRFLOW_CTX_TASK_ID='add_postgre' AIRFLOW_CTX_EXECUTION_DATE='2025-09-05T11:09:55.305363+00:00' AIRFLOW_CTX_TRY_NUMBER='3' AIRFLOW_CTX_DAG_RUN_ID='manual__2025-09-05T11:09:55.305363+00:00'
[2025-09-05T11:19:30.059+0000] {taskinstance.py:430} INFO - ::endgroup::
[2025-09-05T11:20:05.050+0000] {add_postgre.py:46} ERROR - ❌ Lỗi trong add_postgres: unsupported operand type(s) for +: 'Tag' and 'int'
[2025-09-05T11:20:05.051+0000] {taskinstance.py:441} INFO - ::group::Post task execution logs
[2025-09-05T11:20:05.051+0000] {taskinstance.py:2905} ERROR - Task failed with exception
Traceback (most recent call last):
  File "/opt/airflow/dags/utils/new_pipeline/vietstock_ngay.py", line 68, in vietstock
    driver.execute_script("arguments[0].click();", button)
  File "/home/airflow/.local/lib/python3.10/site-packages/selenium/webdriver/remote/webdriver.py", line 551, in execute_script
    return self.execute(command, {"script": script, "args": converted_args})["value"]
  File "/home/airflow/.local/lib/python3.10/site-packages/selenium/webdriver/remote/webdriver.py", line 454, in execute
    self.error_handler.check_response(response)
  File "/home/airflow/.local/lib/python3.10/site-packages/selenium/webdriver/remote/errorhandler.py", line 232, in check_response
    raise exception_class(message, screen, stacktrace)
selenium.common.exceptions.WebDriverException: Message: tab crashed
  (Session info: chrome=138.0.7204.183)
Stacktrace:
#0 0x5613a5e757da <unknown>
#1 0x5613a591a133 <unknown>
#2 0x5613a590391e <unknown>
#3 0x5613a5902a4d <unknown>
#4 0x5613a590249a <unknown>
#5 0x5613a5902175 <unknown>
#6 0x5613a58fffd5 <unknown>
#7 0x5613a590092f <unknown>
#8 0x5613a590f3e3 <unknown>
#9 0x5613a592883e <unknown>
#10 0x5613a592f07b <unknown>
#11 0x5613a5901070 <unknown>
#12 0x5613a5927f83 <unknown>
#13 0x5613a59b75f6 <unknown>
#14 0x5613a5991683 <unknown>
#15 0x5613a595db5b <unknown>
#16 0x5613a595ef31 <unknown>
#17 0x5613a5e3a72b <unknown>
#18 0x5613a5e3e534 <unknown>
#19 0x5613a5e21229 <unknown>
#20 0x5613a5e3f0d8 <unknown>
#21 0x5613a5e0561f <unknown>
#22 0x5613a5e62dd8 <unknown>
#23 0x5613a5e62fb6 <unknown>
#24 0x5613a5e74af6 <unknown>
#25 0x7f28ebcb0134 <unknown>


During handling of the above exception, another exception occurred:

Traceback (most recent call last):
  File "/home/airflow/.local/lib/python3.10/site-packages/airflow/models/taskinstance.py", line 465, in _execute_task
    result = _execute_callable(context=context, **execute_callable_kwargs)
  File "/home/airflow/.local/lib/python3.10/site-packages/airflow/models/taskinstance.py", line 432, in _execute_callable
    return execute_callable(context=context, **execute_callable_kwargs)
  File "/home/airflow/.local/lib/python3.10/site-packages/airflow/models/baseoperator.py", line 400, in wrapper
    return func(self, *args, **kwargs)
  File "/home/airflow/.local/lib/python3.10/site-packages/airflow/operators/python.py", line 235, in execute
    return_value = self.execute_callable()
  File "/home/airflow/.local/lib/python3.10/site-packages/airflow/operators/python.py", line 252, in execute_callable
    return self.python_callable(*self.op_args, **self.op_kwargs)
  File "/opt/airflow/dags/utils/new_pipeline/add_postgre.py", line 11, in add_postgres
    df=tintuc()
  File "/opt/airflow/dags/utils/new_pipeline/merge.py", line 7, in tintuc
    df1=vietstock()
  File "/opt/airflow/dags/utils/new_pipeline/vietstock_ngay.py", line 73, in vietstock
    print(f"Không thể nhấn nút 'Xem thêm' lần {i+1}: {e}")
TypeError: unsupported operand type(s) for +: 'Tag' and 'int'
[2025-09-05T11:20:05.065+0000] {taskinstance.py:1206} INFO - Marking task as UP_FOR_RETRY. dag_id=news_pipeline, task_id=add_postgre, run_id=manual__2025-09-05T11:09:55.305363+00:00, execution_date=20250905T110955, start_date=20250905T111929, end_date=20250905T112005
[2025-09-05T11:20:05.082+0000] {standard_task_runner.py:110} ERROR - Failed to execute job 114380 for task add_postgre (unsupported operand type(s) for +: 'Tag' and 'int'; 3196853)
[2025-09-05T11:20:05.143+0000] {local_task_job_runner.py:240} INFO - Task exited with return code 1
[2025-09-05T11:20:05.174+0000] {taskinstance.py:3498} INFO - 0 downstream tasks scheduled from follow-on schedule check
[2025-09-05T11:20:05.175+0000] {local_task_job_runner.py:222} INFO - ::endgroup::
