[2025-09-07T16:36:01.671+0000] {local_task_job_runner.py:120} INFO - ::group::Pre task execution logs
[2025-09-07T16:36:01.711+0000] {taskinstance.py:2076} INFO - Dependencies all met for dep_context=non-requeueable deps ti=<TaskInstance: foreign_1_live.save_foreign_1 scheduled__2025-09-07T16:35:00+00:00 [queued]>
[2025-09-07T16:36:01.724+0000] {taskinstance.py:2076} INFO - Dependencies all met for dep_context=requeueable deps ti=<TaskInstance: foreign_1_live.save_foreign_1 scheduled__2025-09-07T16:35:00+00:00 [queued]>
[2025-09-07T16:36:01.725+0000] {taskinstance.py:2306} INFO - Starting attempt 1 of 11
[2025-09-07T16:36:01.746+0000] {taskinstance.py:2330} INFO - Executing <Task(PythonOperator): save_foreign_1> on 2025-09-07 16:35:00+00:00
[2025-09-07T16:36:01.756+0000] {standard_task_runner.py:63} INFO - Started process 227903 to run task
[2025-09-07T16:36:01.760+0000] {standard_task_runner.py:90} INFO - Running: ['***', 'tasks', 'run', 'foreign_1_live', 'save_foreign_1', 'scheduled__2025-09-07T16:35:00+00:00', '--job-id', '149667', '--raw', '--subdir', 'DAGS_FOLDER/dag_foreign_1_live.py', '--cfg-path', '/tmp/tmprxl65b0s']
[2025-09-07T16:36:01.763+0000] {standard_task_runner.py:91} INFO - Job 149667: Subtask save_foreign_1
[2025-09-07T16:36:01.822+0000] {task_command.py:426} INFO - Running <TaskInstance: foreign_1_live.save_foreign_1 scheduled__2025-09-07T16:35:00+00:00 [running]> on host 8d9cea3aac78
[2025-09-07T16:36:01.930+0000] {taskinstance.py:2648} INFO - Exporting env vars: AIRFLOW_CTX_DAG_OWNER='***' AIRFLOW_CTX_DAG_ID='foreign_1_live' AIRFLOW_CTX_TASK_ID='save_foreign_1' AIRFLOW_CTX_EXECUTION_DATE='2025-09-07T16:35:00+00:00' AIRFLOW_CTX_TRY_NUMBER='1' AIRFLOW_CTX_DAG_RUN_ID='scheduled__2025-09-07T16:35:00+00:00'
[2025-09-07T16:36:01.932+0000] {taskinstance.py:430} INFO - ::endgroup::
[2025-09-07T16:36:01.959+0000] {foreign_1.py:18} INFO - Kết nối DB
[2025-09-07T16:36:02.264+0000] {foreign_1.py:30} ERROR - Lỗi lưu foreign_ALL
Traceback (most recent call last):
  File "/opt/airflow/dags/utils/market_history/foreign/foreign_1.py", line 20, in foreign
    foreign=foreign_history(f"{symbol}")
  File "/opt/airflow/dags/utils/market_history/foreign/foreign_history_1.py", line 49, in foreign_history
    data=data.drop(columns=['group','dataType','timeFrame'])
  File "/home/airflow/.local/lib/python3.10/site-packages/pandas/core/frame.py", line 5344, in drop
    return super().drop(
  File "/home/airflow/.local/lib/python3.10/site-packages/pandas/core/generic.py", line 4711, in drop
    obj = obj._drop_axis(labels, axis, level=level, errors=errors)
  File "/home/airflow/.local/lib/python3.10/site-packages/pandas/core/generic.py", line 4753, in _drop_axis
    new_axis = axis.drop(labels, errors=errors)
  File "/home/airflow/.local/lib/python3.10/site-packages/pandas/core/indexes/base.py", line 7000, in drop
    raise KeyError(f"{labels[mask].tolist()} not found in axis")
KeyError: "['group', 'dataType', 'timeFrame'] not found in axis"
[2025-09-07T16:36:02.274+0000] {foreign_1.py:18} INFO - Kết nối DB
[2025-09-07T16:36:02.551+0000] {foreign_1.py:30} ERROR - Lỗi lưu foreign_HOSE
Traceback (most recent call last):
  File "/opt/airflow/dags/utils/market_history/foreign/foreign_1.py", line 20, in foreign
    foreign=foreign_history(f"{symbol}")
  File "/opt/airflow/dags/utils/market_history/foreign/foreign_history_1.py", line 49, in foreign_history
    data=data.drop(columns=['group','dataType','timeFrame'])
  File "/home/airflow/.local/lib/python3.10/site-packages/pandas/core/frame.py", line 5344, in drop
    return super().drop(
  File "/home/airflow/.local/lib/python3.10/site-packages/pandas/core/generic.py", line 4711, in drop
    obj = obj._drop_axis(labels, axis, level=level, errors=errors)
  File "/home/airflow/.local/lib/python3.10/site-packages/pandas/core/generic.py", line 4753, in _drop_axis
    new_axis = axis.drop(labels, errors=errors)
  File "/home/airflow/.local/lib/python3.10/site-packages/pandas/core/indexes/base.py", line 7000, in drop
    raise KeyError(f"{labels[mask].tolist()} not found in axis")
KeyError: "['group', 'dataType', 'timeFrame'] not found in axis"
[2025-09-07T16:36:02.554+0000] {foreign_1.py:18} INFO - Kết nối DB
[2025-09-07T16:36:02.832+0000] {foreign_1.py:30} ERROR - Lỗi lưu foreign_HNX
Traceback (most recent call last):
  File "/opt/airflow/dags/utils/market_history/foreign/foreign_1.py", line 20, in foreign
    foreign=foreign_history(f"{symbol}")
  File "/opt/airflow/dags/utils/market_history/foreign/foreign_history_1.py", line 49, in foreign_history
    data=data.drop(columns=['group','dataType','timeFrame'])
  File "/home/airflow/.local/lib/python3.10/site-packages/pandas/core/frame.py", line 5344, in drop
    return super().drop(
  File "/home/airflow/.local/lib/python3.10/site-packages/pandas/core/generic.py", line 4711, in drop
    obj = obj._drop_axis(labels, axis, level=level, errors=errors)
  File "/home/airflow/.local/lib/python3.10/site-packages/pandas/core/generic.py", line 4753, in _drop_axis
    new_axis = axis.drop(labels, errors=errors)
  File "/home/airflow/.local/lib/python3.10/site-packages/pandas/core/indexes/base.py", line 7000, in drop
    raise KeyError(f"{labels[mask].tolist()} not found in axis")
KeyError: "['group', 'dataType', 'timeFrame'] not found in axis"
[2025-09-07T16:36:02.835+0000] {foreign_1.py:18} INFO - Kết nối DB
[2025-09-07T16:36:03.123+0000] {foreign_1.py:30} ERROR - Lỗi lưu foreign_UPCOM
Traceback (most recent call last):
  File "/opt/airflow/dags/utils/market_history/foreign/foreign_1.py", line 20, in foreign
    foreign=foreign_history(f"{symbol}")
  File "/opt/airflow/dags/utils/market_history/foreign/foreign_history_1.py", line 49, in foreign_history
    data=data.drop(columns=['group','dataType','timeFrame'])
  File "/home/airflow/.local/lib/python3.10/site-packages/pandas/core/frame.py", line 5344, in drop
    return super().drop(
  File "/home/airflow/.local/lib/python3.10/site-packages/pandas/core/generic.py", line 4711, in drop
    obj = obj._drop_axis(labels, axis, level=level, errors=errors)
  File "/home/airflow/.local/lib/python3.10/site-packages/pandas/core/generic.py", line 4753, in _drop_axis
    new_axis = axis.drop(labels, errors=errors)
  File "/home/airflow/.local/lib/python3.10/site-packages/pandas/core/indexes/base.py", line 7000, in drop
    raise KeyError(f"{labels[mask].tolist()} not found in axis")
KeyError: "['group', 'dataType', 'timeFrame'] not found in axis"
[2025-09-07T16:36:03.125+0000] {python.py:237} INFO - Done. Returned value was: None
[2025-09-07T16:36:03.126+0000] {taskinstance.py:441} INFO - ::group::Post task execution logs
[2025-09-07T16:36:03.144+0000] {taskinstance.py:1206} INFO - Marking task as SUCCESS. dag_id=foreign_1_live, task_id=save_foreign_1, run_id=scheduled__2025-09-07T16:35:00+00:00, execution_date=20250907T163500, start_date=20250907T163601, end_date=20250907T163603
[2025-09-07T16:36:03.217+0000] {local_task_job_runner.py:240} INFO - Task exited with return code 0
[2025-09-07T16:36:03.260+0000] {taskinstance.py:3503} INFO - 4 downstream tasks scheduled from follow-on schedule check
[2025-09-07T16:36:03.262+0000] {local_task_job_runner.py:222} INFO - ::endgroup::
