[2025-09-06T08:30:04.957+0000] {local_task_job_runner.py:120} INFO - ::group::Pre task execution logs
[2025-09-06T08:30:04.986+0000] {taskinstance.py:2076} INFO - Dependencies all met for dep_context=non-requeueable deps ti=<TaskInstance: news_pipeline.add_postgre scheduled__2025-09-05T01:00:00+00:00 [queued]>
[2025-09-06T08:30:04.995+0000] {taskinstance.py:2076} INFO - Dependencies all met for dep_context=requeueable deps ti=<TaskInstance: news_pipeline.add_postgre scheduled__2025-09-05T01:00:00+00:00 [queued]>
[2025-09-06T08:30:04.996+0000] {taskinstance.py:2306} INFO - Starting attempt 17 of 27
[2025-09-06T08:30:05.010+0000] {taskinstance.py:2330} INFO - Executing <Task(PythonOperator): add_postgre> on 2025-09-05 01:00:00+00:00
[2025-09-06T08:30:05.018+0000] {standard_task_runner.py:63} INFO - Started process 4849 to run task
[2025-09-06T08:30:05.023+0000] {standard_task_runner.py:90} INFO - Running: ['***', 'tasks', 'run', 'news_pipeline', 'add_postgre', 'scheduled__2025-09-05T01:00:00+00:00', '--job-id', '128447', '--raw', '--subdir', 'DAGS_FOLDER/dag_news.py', '--cfg-path', '/tmp/tmp1w9xbmfc']
[2025-09-06T08:30:05.026+0000] {standard_task_runner.py:91} INFO - Job 128447: Subtask add_postgre
[2025-09-06T08:30:05.082+0000] {task_command.py:426} INFO - Running <TaskInstance: news_pipeline.add_postgre scheduled__2025-09-05T01:00:00+00:00 [running]> on host c941e39aca90
[2025-09-06T08:30:05.167+0000] {taskinstance.py:2648} INFO - Exporting env vars: AIRFLOW_CTX_DAG_OWNER='***' AIRFLOW_CTX_DAG_ID='news_pipeline' AIRFLOW_CTX_TASK_ID='add_postgre' AIRFLOW_CTX_EXECUTION_DATE='2025-09-05T01:00:00+00:00' AIRFLOW_CTX_TRY_NUMBER='17' AIRFLOW_CTX_DAG_RUN_ID='scheduled__2025-09-05T01:00:00+00:00'
[2025-09-06T08:30:05.168+0000] {taskinstance.py:430} INFO - ::endgroup::
[2025-09-06T08:30:05.230+0000] {logging_mixin.py:188} INFO - Error in vietstock: Message: session not created
from disconnected: unable to connect to renderer; For documentation on this error, please visit: https://www.selenium.dev/documentation/webdriver/troubleshooting/errors#sessionnotcreatedexception
Stacktrace:
#0 0x56080e3d00ee <unknown>
#1 0x56080de38ff1 <unknown>
#2 0x56080de74bcf <unknown>
#3 0x56080de70c0e <unknown>
#4 0x56080de6bfe6 <unknown>
#5 0x56080deb5fff <unknown>
#6 0x56080dea7473 <unknown>
#7 0x56080de78009 <unknown>
#8 0x56080de78b71 <unknown>
#9 0x56080e39b4fa <unknown>
#10 0x56080e39e7c1 <unknown>
#11 0x56080e39e258 <unknown>
#12 0x56080e39ec65 <unknown>
#13 0x56080e3850dc <unknown>
#14 0x56080e39efd1 <unknown>
#15 0x56080e36e25a <unknown>
#16 0x56080e3bd4b5 <unknown>
#17 0x56080e3bd6ae <unknown>
#18 0x56080e3cec25 <unknown>
#19 0x7f932de11134 <unknown>
[2025-09-06T08:30:05.230+0000] {logging_mixin.py:188} INFO - Error in tinnhanh: Message: session not created
from disconnected: unable to connect to renderer; For documentation on this error, please visit: https://www.selenium.dev/documentation/webdriver/troubleshooting/errors#sessionnotcreatedexception
Stacktrace:
#0 0x5630c22030ee <unknown>
#1 0x5630c1c6bff1 <unknown>
#2 0x5630c1ca7bcf <unknown>
#3 0x5630c1ca3c0e <unknown>
#4 0x5630c1c9efe6 <unknown>
#5 0x5630c1ce8fff <unknown>
#6 0x5630c1cda473 <unknown>
#7 0x5630c1cab009 <unknown>
#8 0x5630c1cabb71 <unknown>
#9 0x5630c21ce4fa <unknown>
#10 0x5630c21d17c1 <unknown>
#11 0x5630c21d1258 <unknown>
#12 0x5630c21d1c65 <unknown>
#13 0x5630c21b80dc <unknown>
#14 0x5630c21d1fd1 <unknown>
#15 0x5630c21a125a <unknown>
#16 0x5630c21f04b5 <unknown>
#17 0x5630c21f06ae <unknown>
#18 0x5630c2201c25 <unknown>
#19 0x7fa35f66b134 <unknown>
[2025-09-06T08:30:05.230+0000] {logging_mixin.py:188} INFO - Error in cafef: Message: session not created
from disconnected: unable to connect to renderer; For documentation on this error, please visit: https://www.selenium.dev/documentation/webdriver/troubleshooting/errors#sessionnotcreatedexception
Stacktrace:
#0 0x564a7eca60ee <unknown>
#1 0x564a7e70eff1 <unknown>
#2 0x564a7e74abcf <unknown>
#3 0x564a7e746c0e <unknown>
#4 0x564a7e741fe6 <unknown>
#5 0x564a7e78bfff <unknown>
#6 0x564a7e77d473 <unknown>
#7 0x564a7e74e009 <unknown>
#8 0x564a7e74eb71 <unknown>
#9 0x564a7ec714fa <unknown>
#10 0x564a7ec747c1 <unknown>
#11 0x564a7ec74258 <unknown>
#12 0x564a7ec74c65 <unknown>
#13 0x564a7ec5b0dc <unknown>
#14 0x564a7ec74fd1 <unknown>
#15 0x564a7ec4425a <unknown>
#16 0x564a7ec934b5 <unknown>
#17 0x564a7ec936ae <unknown>
#18 0x564a7eca4c25 <unknown>
#19 0x7f3356693134 <unknown>
[2025-09-06T08:30:05.231+0000] {add_postgre.py:48} ERROR - ❌ Lỗi trong add_postgres: No objects to concatenate
[2025-09-06T08:30:05.231+0000] {taskinstance.py:441} INFO - ::group::Post task execution logs
[2025-09-06T08:30:05.232+0000] {taskinstance.py:2905} ERROR - Task failed with exception
Traceback (most recent call last):
  File "/home/airflow/.local/lib/python3.10/site-packages/airflow/models/taskinstance.py", line 465, in _execute_task
    result = _execute_callable(context=context, **execute_callable_kwargs)
  File "/home/airflow/.local/lib/python3.10/site-packages/airflow/models/taskinstance.py", line 432, in _execute_callable
    return execute_callable(context=context, **execute_callable_kwargs)
  File "/home/airflow/.local/lib/python3.10/site-packages/airflow/models/baseoperator.py", line 400, in wrapper
    return func(self, *args, **kwargs)
  File "/home/airflow/.local/lib/python3.10/site-packages/airflow/operators/python.py", line 235, in execute
    return_value = self.execute_callable()
  File "/home/airflow/.local/lib/python3.10/site-packages/airflow/operators/python.py", line 252, in execute_callable
    return self.python_callable(*self.op_args, **self.op_kwargs)
  File "/opt/airflow/dags/utils/new_pipeline/add_postgre.py", line 15, in add_postgres
    df=tintuc()
  File "/opt/airflow/dags/utils/new_pipeline/merge.py", line 31, in tintuc
    return asyncio.run(tintuc_async())
  File "/usr/local/lib/python3.10/asyncio/runners.py", line 44, in run
    return loop.run_until_complete(main)
  File "/usr/local/lib/python3.10/asyncio/base_events.py", line 649, in run_until_complete
    return future.result()
  File "/opt/airflow/dags/utils/new_pipeline/merge.py", line 26, in tintuc_async
    df_all = pd.concat(results, ignore_index=True)
  File "/home/airflow/.local/lib/python3.10/site-packages/pandas/core/reshape/concat.py", line 380, in concat
    op = _Concatenator(
  File "/home/airflow/.local/lib/python3.10/site-packages/pandas/core/reshape/concat.py", line 443, in __init__
    objs, keys = self._clean_keys_and_objs(objs, keys)
  File "/home/airflow/.local/lib/python3.10/site-packages/pandas/core/reshape/concat.py", line 505, in _clean_keys_and_objs
    raise ValueError("No objects to concatenate")
ValueError: No objects to concatenate
[2025-09-06T08:30:05.241+0000] {taskinstance.py:1206} INFO - Marking task as UP_FOR_RETRY. dag_id=news_pipeline, task_id=add_postgre, run_id=scheduled__2025-09-05T01:00:00+00:00, execution_date=20250905T010000, start_date=20250906T083004, end_date=20250906T083005
[2025-09-06T08:30:05.252+0000] {standard_task_runner.py:110} ERROR - Failed to execute job 128447 for task add_postgre (No objects to concatenate; 4849)
[2025-09-06T08:30:05.274+0000] {local_task_job_runner.py:240} INFO - Task exited with return code 1
[2025-09-06T08:30:05.310+0000] {taskinstance.py:3498} INFO - 0 downstream tasks scheduled from follow-on schedule check
[2025-09-06T08:30:05.311+0000] {local_task_job_runner.py:222} INFO - ::endgroup::
